
CUDA availability: True
Traceback (most recent call last):
  File "main.py", line 87, in <module>
    main()
  File "main.py", line 83, in main
    model_trained = train(dataset, config,  device)
  File "main.py", line 48, in train
    loss, timing_loss, choice_loss  = model(arr_b.float(), arr_c.float(), arr_delta_time.float(), event_data, non_event_data, estimate_length, choice_data_dict)
  File "/home/dalab5/miniconda3/envs/GNN/lib/python3.8/site-packages/torch/nn/modules/module.py", line 889, in _call_impl
    result = self.forward(*input, **kwargs)
  File "/home/dalab5/Projects/MA_packed/model.py", line 180, in forward
    event_lambda = self.timing_net(mat_b, mat_c, event_data) # (L3, )
  File "/home/dalab5/miniconda3/envs/GNN/lib/python3.8/site-packages/torch/nn/modules/module.py", line 889, in _call_impl
    result = self.forward(*input, **kwargs)
  File "/home/dalab5/Projects/MA_packed/model.py", line 229, in forward
    b = mat_b[arr_b_idx] # (L3, embedding_b)
IndexError: too many indices for tensor of dimension 3