Traceback (most recent call last):
  File "main.py", line 88, in <module>
    main()
  File "main.py", line 84, in main
    model_trained = train(dataset, config,  device)
  File "main.py", line 48, in train
    loss, timing_loss, choice_loss  = model(arr_b.float(), arr_c.float(), arr_delta_time.float(), event_data, non_event_data, estimate_length, choice_data_dict)
  File "/home/dalab5/miniconda3/envs/GNN/lib/python3.8/site-packages/torch/nn/modules/module.py", line 889, in _call_impl
    result = self.forward(*input, **kwargs)
  File "/home/dalab5/Projects/MA_packed/model.py", line 190, in forward
    event_choice_loss = self.choice_net(mat_b, mat_c, choice_data_dict, self.s_year, self.e_year)
  File "/home/dalab5/miniconda3/envs/GNN/lib/python3.8/site-packages/torch/nn/modules/module.py", line 889, in _call_impl
    result = self.forward(*input, **kwargs)
  File "/home/dalab5/Projects/MA_packed/model.py", line 288, in forward
    dict_idx, true_tar_idxs_i, features_i, edges_i = choice_data_dict[year] # list=:[N_i_1], arrays: (N_i_1, 22) , (2, |E|)
IndexError: list index out of range
CUDA availability: True