2021-10-31 23:48:19,806 INFO    MainThread:33655 [wandb_setup.py:_flush():71] setting env: {}
2021-10-31 23:48:19,806 INFO    MainThread:33655 [wandb_setup.py:_flush():71] setting login settings: {}
2021-10-31 23:48:19,806 INFO    MainThread:33655 [wandb_init.py:_log_setup():357] Logging user logs to /home/dalab5/Projects/MA_packed/wandb/run-20211031_234819-w3fgdzk7/logs/debug.log
2021-10-31 23:48:19,806 INFO    MainThread:33655 [wandb_init.py:_log_setup():358] Logging internal logs to /home/dalab5/Projects/MA_packed/wandb/run-20211031_234819-w3fgdzk7/logs/debug-internal.log
2021-10-31 23:48:19,806 INFO    MainThread:33655 [wandb_init.py:init():390] calling init triggers
2021-10-31 23:48:19,807 INFO    MainThread:33655 [wandb_init.py:init():395] wandb.init called with sweep_config: {}
config: {}
2021-10-31 23:48:19,807 INFO    MainThread:33655 [wandb_init.py:init():435] starting backend
2021-10-31 23:48:19,807 INFO    MainThread:33655 [backend.py:_multiprocessing_setup():95] multiprocessing start_methods=fork,spawn,forkserver, using: spawn
2021-10-31 23:48:19,814 INFO    MainThread:33655 [backend.py:ensure_launched():199] starting backend process...
2021-10-31 23:48:19,819 INFO    MainThread:33655 [backend.py:ensure_launched():204] started backend process with pid: 33669
2021-10-31 23:48:19,820 INFO    MainThread:33655 [wandb_init.py:init():444] backend started and connected
2021-10-31 23:48:19,821 INFO    MainThread:33655 [wandb_init.py:init():503] updated telemetry
2021-10-31 23:48:19,822 INFO    MainThread:33655 [wandb_init.py:init():533] communicating current version
2021-10-31 23:48:20,439 INFO    MainThread:33655 [wandb_init.py:init():538] got version response 
2021-10-31 23:48:20,439 INFO    MainThread:33655 [wandb_init.py:init():548] communicating run to backend with 30 second timeout
2021-10-31 23:48:20,559 INFO    MainThread:33655 [wandb_init.py:init():576] starting run threads in backend
2021-10-31 23:48:22,308 INFO    MainThread:33655 [wandb_run.py:_console_start():1693] atexit reg
2021-10-31 23:48:22,309 INFO    MainThread:33655 [wandb_run.py:_redirect():1567] redirect: SettingsConsole.REDIRECT
2021-10-31 23:48:22,310 INFO    MainThread:33655 [wandb_run.py:_redirect():1572] Redirecting console.
2021-10-31 23:48:22,313 INFO    MainThread:33655 [wandb_run.py:_redirect():1628] Redirects installed.
2021-10-31 23:48:22,313 INFO    MainThread:33655 [wandb_init.py:init():603] run started, returning control to user process
2021-10-31 23:48:38,667 INFO    MainThread:33655 [wandb_run.py:_atexit_cleanup():1663] got exitcode: 255
2021-10-31 23:48:38,667 INFO    MainThread:33655 [wandb_run.py:_restore():1635] restore
2021-10-31 23:48:39,962 INFO    MainThread:33655 [wandb_run.py:_restore():1635] restore
2021-10-31 23:48:42,784 ERROR   MainThread:33655 [wandb_run.py:_atexit_cleanup():1681] Problem finishing run
Traceback (most recent call last):
  File "/home/dalab5/miniconda3/envs/GNN/lib/python3.8/site-packages/wandb/sdk/wandb_run.py", line 1671, in _atexit_cleanup
    self._on_finish()
  File "/home/dalab5/miniconda3/envs/GNN/lib/python3.8/site-packages/wandb/sdk/wandb_run.py", line 1817, in _on_finish
    self._console_stop()  # TODO: there's a race here with jupyter console logging
  File "/home/dalab5/miniconda3/envs/GNN/lib/python3.8/site-packages/wandb/sdk/wandb_run.py", line 1711, in _console_stop
    self._restore()
  File "/home/dalab5/miniconda3/envs/GNN/lib/python3.8/site-packages/wandb/sdk/wandb_run.py", line 1639, in _restore
    self._out_redir.uninstall()
  File "/home/dalab5/miniconda3/envs/GNN/lib/python3.8/site-packages/wandb/sdk/lib/redirect.py", line 747, in uninstall
    self._emulator_write_thread.join(timeout=5)
  File "/home/dalab5/miniconda3/envs/GNN/lib/python3.8/threading.py", line 1015, in join
    self._wait_for_tstate_lock(timeout=max(timeout, 0))
  File "/home/dalab5/miniconda3/envs/GNN/lib/python3.8/threading.py", line 1027, in _wait_for_tstate_lock
    elif lock.acquire(block, timeout):
  File "/home/dalab5/miniconda3/envs/GNN/lib/python3.8/site-packages/wandb/sdk/lib/redirect.py", line 649, in handler
    self.handle_window_size_change()
  File "/home/dalab5/miniconda3/envs/GNN/lib/python3.8/site-packages/wandb/sdk/lib/redirect.py", line 680, in handle_window_size_change
    fcntl.ioctl(fd, termios.TIOCSWINSZ, win_size)
OSError: [Errno 9] Bad file descriptor
